Workbook

Sheet Posterior Summary
A1: Eight Schools: Hierarchical Model (non-centered) - Posterior Summary
A2: Stan output: 4 chains, iter=1000, warmup=500, thin=1. Blue = values copied from Stan output; black = formulas.
A3: Post-warmup draws | B3: 2000 | C3: (4 chains x 500)
A5: Parameter | B5: Type | C5: Mean | D5: se_mean | E5: SD | F5: 2.5% | G5: 25% | H5: 50% | I5: 75% | J5: 97.5% | K5: n_eff | L5: Rhat | M5: n_eff / draws | N5: 95% interval includes 0? | O5: Rhat <= 1.01?
A6: alpha | B6: Population | C6: 7.73 | D6: 0.12 | E6: 4.63 | F6: -1.21 | G6: 4.55 | H6: 7.7 | I6: 10.82 | J6: 16.67 | K6: 1390 | L6: 1 | M6: =K6/$B$3 -> 0.695 | N6: =IF(AND(F6<=0,J6>=0),"Yes","No") -> Yes | O6: =IF(L6<=1.01,"Yes","No") -> Yes
A7: beta | B7: Population | C7: 4.87 | D7: 0.11 | E7: 3.82 | F7: 0.23 | G7: 1.84 | H7: 3.98 | I7: 6.96 | J7: 14.28 | K7: 1167 | L7: 1 | M7: =K7/$B$3 -> 0.5835 | N7: =IF(AND(F7<=0,J7>=0),"Yes","No") -> No | O7: =IF(L7<=1.01,"Yes","No") -> Yes
A8: eta[1] | B8: School offset | C8: 0.36 | D8: 0.02 | E8: 1 | F8: -1.68 | G8: -0.32 | H8: 0.36 | I8: 1.04 | J8: 2.29 | K8: 1988 | L8: 1 | M8: =K8/$B$3 -> 0.994 | N8: =IF(AND(F8<=0,J8>=0),"Yes","No") -> Yes | O8: =IF(L8<=1.01,"Yes","No") -> Yes
A9: eta[2] | B9: School offset | C9: 0 | D9: 0.02 | E9: 0.88 | F9: -1.75 | G9: -0.59 | H9: 0.01 | I9: 0.56 | J9: 1.79 | K9: 1992 | L9: 1 | M9: =K9/$B$3 -> 0.996 | N9: =IF(AND(F9<=0,J9>=0),"Yes","No") -> Yes | O9: =IF(L9<=1.01,"Yes","No") -> Yes
A10: eta[3] | B10: School offset | C10: -0.15 | D10: 0.02 | E10: 0.98 | F10: -2.03 | G10: -0.82 | H10: -0.15 | I10: 0.53 | J10: 1.76 | K10: 1924 | L10: 1 | M10: =K10/$B$3 -> 0.962 | N10: =IF(AND(F10<=0,J10>=0),"Yes","No") -> Yes | O10: =IF(L10<=1.01,"Yes","No") -> Yes
A11: eta[4] | B11: School offset | C11: -0.05 | D11: 0.02 | E11: 0.89 | F11: -1.75 | G11: -0.66 | H11: -0.04 | I11: 0.52 | J11: 1.69 | K11: 2700 | L11: 1 | M11: =K11/$B$3 -> 1.35 | N11: =IF(AND(F11<=0,J11>=0),"Yes","No") -> Yes | O11: =IF(L11<=1.01,"Yes","No") -> Yes
A12: eta[5] | B12: School offset | C12: -0.27 | D12: 0.02 | E12: 0.91 | F12: -1.99 | G12: -0.9 | H12: -0.3 | I12: 0.34 | J12: 1.57 | K12: 2008 | L12: 1 | M12: =K12/$B$3 -> 1.004 | N12: =IF(AND(F12<=0,J12>=0),"Yes","No") -> Yes | O12: =IF(L12<=1.01,"Yes","No") -> Yes
A13: eta[6] | B13: School offset | C13: -0.16 | D13: 0.02 | E13: 0.94 | F13: -2.02 | G13: -0.79 | H13: -0.17 | I13: 0.46 | J13: 1.7 | K13: 2245 | L13: 1 | M13: =K13/$B$3 -> 1.1225 | N13: =IF(AND(F13<=0,J13>=0),"Yes","No") -> Yes | O13: =IF(L13<=1.01,"Yes","No") -> Yes
A14: eta[7] | B14: School offset | C14: 0.31 | D14: 0.02 | E14: 0.93 | F14: -1.55 | G14: -0.34 | H14: 0.34 | I14: 0.92 | J14: 2.11 | K14: 2342 | L14: 1 | M14: =K14/$B$3 -> 1.171 | N14: =IF(AND(F14<=0,J14>=0),"Yes","No") -> Yes | O14: =IF(L14<=1.01,"Yes","No") -> Yes
A15: eta[8] | B15: School offset | C15: 0.06 | D15: 0.02 | E15: 0.96 | F15: -1.77 | G15: -0.6 | H15: 0.03 | I15: 0.72 | J15: 1.99 | K15: 2201 | L15: 1 | M15: =K15/$B$3 -> 1.1005 | N15: =IF(AND(F15<=0,J15>=0),"Yes","No") -> Yes | O15: =IF(L15<=1.01,"Yes","No") -> Yes
A16: mu[1] | B16: School effect | C16: 10.4 | D16: 0.18 | E16: 7.17 | F16: -1.31 | G16: 5.85 | H16: 9.48 | I16: 14.27 | J16: 27.2 | K16: 1591 | L16: 1 | M16: =K16/$B$3 -> 0.7955 | N16: =IF(AND(F16<=0,J16>=0),"Yes","No") -> Yes | O16: =IF(L16<=1.01,"Yes","No") -> Yes
A17: mu[2] | B17: School effect | C17: 7.85 | D17: 0.12 | E17: 5.58 | F17: -3.22 | G17: 4.33 | H17: 7.88 | I17: 11.37 | J17: 19.37 | K17: 2323 | L17: 1 | M17: =K17/$B$3 -> 1.1615 | N17: =IF(AND(F17<=0,J17>=0),"Yes","No") -> Yes | O17: =IF(L17<=1.01,"Yes","No") -> Yes
... A24: lp__ | B24: Log posterior | C24: -5.52 | D24: 0.09 | E24: 2.41 | F24: -10.97 | G24: -6.98 | H24: -5.3 | I24: -3.77 | J24: -1.54 | K24: 733 | L24: 1 | M24: =K24/$B$3 -> 0.3665 | N24: =IF(AND(F24<=0,J24>=0),"Yes","No") -> No | O24: =IF(L24<=1.01,"Yes","No") -> Yes
A26: Convergence check
A27: Max Rhat | C27: =MAX(L6:L24) -> 1
A28: Min n_eff | C28: =MIN(K6:K24) -> 733
A29: All parameters Rhat <= 1.01? | C29: =IF(COUNTIF(O6:O24,"No")=0,"Yes","No") -> Yes
A31: Note: Rhat shown rounded to 2 decimals by Stan (1.00); n_eff / draws > 1 is possible for well-mixing parameters.

Sheet Non-Hier Summary
A1: Eight Schools: Non-Hierarchical (No-Pooling) Model - Posterior Summary
A2: Stan output: 4 chains, iter=1000, warmup=500, thin=1. Model: treatment ~ normal(mu, standard_error), one independent mu per school, flat prior. Blue = copied from Stan output; black = formulas.
A3: Post-warmup draws | B3: 2000 | C3: (4 chains x 500)
A5: Parameter | B5: Type | C5: Mean | D5: se_mean | E5: SD | F5: 2.5% | G5: 25% | H5: 50% | I5: 75% | J5: 97.5% | K5: n_eff | L5: Rhat | M5: n_eff / draws | N5: 95% interval includes 0? | O5: Rhat <= 1.01?
A6: mu[1] | B6: School effect | C6: 28.84 | D6: 0.26 | E6: 14.86 | F6: 0.62 | G6: 18.72 | H6: 28.51 | I6: 39 | J6: 58.11 | K6: 3193 | L6: 1 | M6: =K6/$B$3 -> 1.5965 | N6: =IF(AND(F6<=0,J6>=0),"Yes","No") -> No | O6: =IF(L6<=1.01,"Yes","No") -> Yes
A7: mu[2] | B7: School effect | C7: 7.86 | D7: 0.19 | E7: 10.16 | F7: -12.43 | G7: 1.03 | H7: 7.84 | I7: 14.65 | J7: 27.77 | K7: 2980 | L7: 1 | M7: =K7/$B$3 -> 1.49 | N7: =IF(AND(F7<=0,J7>=0),"Yes","No") -> Yes | O7: =IF(L7<=1.01,"Yes","No") -> Yes
A8: mu[3] | B8: School effect | C8: -2.96 | D8: 0.32 | E8: 16.83 | F8: -34.93 | G8: -14.57 | H8: -3.6 | I8: 8.62 | J8: 29.49 | K8: 2827 | L8: 1 | M8: =K8/$B$3 -> 1.4135 | N8: =IF(AND(F8<=0,J8>=0),"Yes","No") -> Yes | O8: =IF(L8<=1.01,"Yes","No") -> Yes
A9: mu[4] | B9: School effect | C9: 7.08 | D9: 0.19 | E9: 11.03 | F9: -14.55 | G9: -0.2 | H9: 7 | I9: 14.21 | J9: 28.24 | K9: 3275 | L9: 1 | M9: =K9/$B$3 -> 1.6375 | N9: =IF(AND(F9<=0,J9>=0),"Yes","No") -> Yes | O9: =IF(L9<=1.01,"Yes","No") -> Yes
A10: mu[5] | B10: School effect | C10: -0.7 | D10: 0.19 | E10: 9.86 | F10: -19.75 | G10: -7.15 | H10: -0.82 | I10: 5.53 | J10: 19.4 | K10: 2600 | L10: 1 | M10: =K10/$B$3 -> 1.3 | N10: =IF(AND(F10<=0,J10>=0),"Yes","No") -> Yes | O10: =IF(L10<=1.01,"Yes","No") -> Yes
A11: mu[6] | B11: School effect | C11: 0.58 | D11: 0.21 | E11: 11.26 | F11: -20.95 | G11: -6.88 | H11: 0.47 | I11: 8.2 | J11: 22.18 | K11: 2829 | L11: 1 | M11: =K11/$B$3 -> 1.4145 | N11: =IF(AND(F11<=0,J11>=0),"Yes","No") -> Yes | O11: =IF(L11<=1.01,"Yes","No") -> Yes
A12: mu[7] | B12: School effect | C12: 17.82 | D12: 0.19 | E12: 10.75 | F12: -3.86 | G12: 10.86 | H12: 17.72 | I12: 25.09 | J12: 38.84 | K12: 3211 | L12: 1 | M12: =K12/$B$3 -> 1.6055 | N12: =IF(AND(F12<=0,J12>=0),"Yes","No") -> Yes | O12: =IF(L12<=1.01,"Yes","No") -> Yes
A13: mu[8] | B13: School effect | C13: 11.85 | D13: 0.33 | E13: 16.98 | F13: -21.49 | G13: 0.2 | H13: 12.08 | I13: 23.38 | J13: 44.78 | K13: 2609 | L13: 1 | M13: =K13/$B$3 -> 1.3045 | N13: =IF(AND(F13<=0,J13>=0),"Yes","No") -> Yes | O13: =IF(L13<=1.01,"Yes","No") -> Yes
A14: lp__ | B14: Log posterior | C14: -4.07 | D14: 0.08 | E14: 2.08 | F14: -9.06 | G14: -5.26 | H14: -3.68 | I14: -2.55 | J14: -1.07 | K14: 643 | L14: 1.01 | M14: =K14/$B$3 -> 0.3215 | N14: =IF(AND(F14<=0,J14>=0),"Yes","No") -> No | O14: =IF(L14<=1.01,"Yes","No") -> Yes
A16: Convergence check
A17: Max Rhat | C17: =MAX(L6:L14) -> 1.01
A18: Min n_eff | C18: =MIN(K6:K14) -> 643
A19: All parameters Rhat <= 1.01? | C19: =IF(COUNTIF(O6:O14,"No")=0,"Yes","No") -> Yes
A21: Note: lp__ has Rhat 1.01 and n_eff 643 (the lowest), which is acceptable; all mu parameters have Rhat 1.00 and n_eff above 2,600.

Sheet Model Comparison
A1: Hierarchical vs Non-Hierarchical: School Effects (mu)
A2: Hierarchical = non-centered model with beta ~ half-normal(0,10) (sheet 'Posterior Summary'); Non-hierarchical = independent mu per school ('Non-Hier Summary'). Green = links to other sheets; black = formulas.
A4: School | B4: Raw estimate | C4: Raw SE | D4: Non-hier mean | E4: Hier mean | F4: Diff (Hier - Non-hier) | G4: Non-hier SD | H4: Hier SD | I4: SD ratio (Hier / Non-hier) | J4: Non-hier 2.5% | K4: Non-hier 97.5% | L4: Non-hier 95% width | M4: Hier 2.5% | N4: Hier 97.5% | O4: Hier 95% width | P4: Width reduction (Hier vs Non-hier) | Q4: Non-hier interval includes 0? | R4: Hier interval includes 0?
A5: A | B5: ='School Shrinkage'!B5 -> 28.39 | C5: ='School Shrinkage'!C5 -> 14.9 | D5: ='Non-Hier Summary'!C6 -> 28.84 | E5: ='Posterior Summary'!C16 -> 10.4 | F5: =E5-D5 -> -18.44 | G5: ='Non-Hier Summary'!E6 -> 14.86 | H5: ='Posterior Summary'!E16 -> 7.17 | I5: =H5/G5 -> 0.48250336 | J5: ='Non-Hier Summary'!F6 -> 0.62 | K5: ='Non-Hier Summary'!J6 -> 58.11 | L5: =K5-J5 -> 57.49 | M5: ='Posterior Summary'!F16 -> -1.31 | N5: ='Posterior Summary'!J16 -> 27.2 | O5: =N5-M5 -> 28.51 | P5: =1-O5/L5 -> 0.50408767 | Q5: =IF(AND(J5<=0,K5>=0),"Yes","No") -> No | R5: =IF(AND(M5<=0,N5>=0),"Yes","No") -> Yes
A6: B | B6: ='School Shrinkage'!B6 -> 7.94 | C6: ='School Shrinkage'!C6 -> 10.2 | D6: ='Non-Hier Summary'!C7 -> 7.86 | E6: ='Posterior Summary'!C17 -> 7.85 | F6: =E6-D6 -> -0.01 | G6: ='Non-Hier Summary'!E7 -> 10.16 | H6: ='Posterior Summary'!E17 -> 5.58 | I6: =H6/G6 -> 0.5492126 | J6: ='Non-Hier Summary'!F7 -> -12.43 | K6: ='Non-Hier Summary'!J7 -> 27.77 | L6: =K6-J6 -> 40.2 | M6: ='Posterior Summary'!F17 -> -3.22 | N6: ='Posterior Summary'!J17 -> 19.37 | O6: =N6-M6 -> 22.59 | P6: =1-O6/L6 -> 0.4380597 | Q6: =IF(AND(J6<=0,K6>=0),"Yes","No") -> Yes | R6: =IF(AND(M6<=0,N6>=0),"Yes","No") -> Yes
A7: C | B7: ='School Shrinkage'!B7 -> -2.75 | C7: ='School Shrinkage'!C7 -> 16.3 | D7: ='Non-Hier Summary'!C8 -> -2.96 | E7: ='Posterior Summary'!C18 -> 6.74 | F7: =E7-D7 -> 9.7 | G7: ='Non-Hier Summary'!E8 -> 16.83 | H7: ='Posterior Summary'!E18 -> 6.76 | I7: =H7/G7 -> 0.4016637 | J7: ='Non-Hier Summary'!F8 -> -34.93 | K7: ='Non-Hier Summary'!J8 -> 29.49 | L7: =K7-J7 -> 64.42 | M7: ='Posterior Summary'!F18 -> -8.15 | N7: ='Posterior Summary'!J18 -> 18.92 | O7: =N7-M7 -> 27.07 | P7: =1-O7/L7 -> 0.57978889 | Q7: =IF(AND(J7<=0,K7>=0),"Yes","No") -> Yes | R7: =IF(AND(M7<=0,N7>=0),"Yes","No") -> Yes
A8: D | B8: ='School Shrinkage'!B8 -> 6.82 | C8: ='School Shrinkage'!C8 -> 11 | D8: ='Non-Hier Summary'!C9 -> 7.08 | E8: ='Posterior Summary'!C19 -> 7.47 | F8: =E8-D8 -> 0.39 | G8: ='Non-Hier Summary'!E9 -> 11.03 | H8: ='Posterior Summary'!E19 -> 5.79 | I8: =H8/G8 -> 0.524932 | J8: ='Non-Hier Summary'!F9 -> -14.55 | K8: ='Non-Hier Summary'!J9 -> 28.24 | L8: =K8-J8 -> 42.79 | M8: ='Posterior Summary'!F19 -> -3.78 | N8: ='Posterior Summary'!J19 -> 19.38 | O8: =N8-M8 -> 23.16 | P8: =1-O8/L8 -> 0.45875204 | Q8: =IF(AND(J8<=0,K8>=0),"Yes","No") -> Yes | R8: =IF(AND(M8<=0,N8>=0),"Yes","No") -> Yes
A9: E | B9: ='School Shrinkage'!B9 -> -0.64 | C9: ='School Shrinkage'!C9 -> 9.4 | D9: ='Non-Hier Summary'!C10 -> -0.7 | E9: ='Posterior Summary'!C20 -> 6 | F9: =E9-D9 -> 6.7 | G9: ='Non-Hier Summary'!E10 -> 9.86 | H9: ='Posterior Summary'!E20 -> 5.83 | I9: =H9/G9 -> 0.59127789 | J9: ='Non-Hier Summary'!F10 -> -19.75 | K9: ='Non-Hier Summary'!J10 -> 19.4 | L9: =K9-J9 -> 39.15 | M9: ='Posterior Summary'!F20 -> -6.37 | N9: ='Posterior Summary'!J20 -> 16.51 | O9: =N9-M9 -> 22.88 | P9: =1-O9/L9 -> 0.4155811 | Q9: =IF(AND(J9<=0,K9>=0),"Yes","No") -> Yes | R9: =IF(AND(M9<=0,N9>=0),"Yes","No") -> Yes
A10: F | B10: ='School Shrinkage'!B10 -> 0.63 | C10: ='School Shrinkage'!C10 -> 11.4 | D10: ='Non-Hier Summary'!C11 -> 0.58 | E10: ='Posterior Summary'!C21 -> 6.57 | F10: =E10-D10 -> 5.99 | G10: ='Non-Hier Summary'!E11 -> 11.26 | H10: ='Posterior Summary'!E21 -> 6.23 | I10: =H10/G10 -> 0.55328597 | J10: ='Non-Hier Summary'!F11 -> -20.95 | K10: ='Non-Hier Summary'!J11 -> 22.18 | L10: =K10-J10 -> 43.13 | M10: ='Posterior Summary'!F21 -> -6.95 | N10: ='Posterior Summary'!J21 -> 17.86 | O10: =N10-M10 -> 24.81 | P10: =1-O10/L10 -> 0.42476235 | Q10: =IF(AND(J10<=0,K10>=0),"Yes","No") -> Yes | R10: =IF(AND(M10<=0,N10>=0),"Yes","No") -> Yes
A11: G | B11: ='School Shrinkage'!B11 -> 18.01 | C11: ='School Shrinkage'!C11 -> 10.4 | D11: ='Non-Hier Summary'!C12 -> 17.82 | E11: ='Posterior Summary'!C22 -> 9.85 | F11: =E11-D11 -> -7.97 | G11: ='Non-Hier Summary'!E12 -> 10.75 | H11: ='Posterior Summary'!E22 -> 6.16 | I11: =H11/G11 -> 0.57302326 | J11: ='Non-Hier Summary'!F12 -> -3.86 | K11: ='Non-Hier Summary'!J12 -> 38.84 | L11: =K11-J11 -> 42.7 | M11: ='Posterior Summary'!F22 -> -1.44 | N11: ='Posterior Summary'!J22 -> 23.72 | O11: =N11-M11 -> 25.16 | P11: =1-O11/L11 -> 0.41077283 | Q11: =IF(AND(J11<=0,K11>=0),"Yes","No") -> Yes | R11: =IF(AND(M11<=0,N11>=0),"Yes","No") -> Yes
A12: H | B12: ='School Shrinkage'!B12 -> 12.16 | C12: ='School Shrinkage'!C12 -> 17.6 | D12: ='Non-Hier Summary'!C13 -> 11.85 | E12: ='Posterior Summary'!C23 -> 8.15 | F12: =E12-D12 -> -3.7 | G12: ='Non-Hier Summary'!E13 -> 16.98 | H12: ='Posterior Summary'!E23 -> 6.54 | I12: =H12/G12 -> 0.38515901 | J12: ='Non-Hier Summary'!F13 -> -21.49 | K12: ='Non-Hier Summary'!J13 -> 44.78 | L12: =K12-J12 -> 66.27 | M12: ='Posterior Summary'!F23 -> -4.32 | N12: ='Posterior Summary'!J23 -> 21.85 | O12: =N12-M12 -> 26.17 | P12: =1-O12/L12 -> 0.60510035 | Q12: =IF(AND(J12<=0,K12>=0),"Yes","No") -> Yes | R12: =IF(AND(M12<=0,N12>=0),"Yes","No") -> Yes
A14: Summary
A15: Metric | B15: Raw data | C15: Non-hierarchical | D15: Hierarchical
A16: Range of school means (max - min) | B16: =MAX(B5:B12)-MIN(B5:B12) -> 31.14 | C16: =MAX(D5:D12)-MIN(D5:D12) -> 31.8 | D16: =MAX(E5:E12)-MIN(E5:E12) -> 4.4
A17: Mean absolute distance from raw estimate | C17: =SUMPRODUCT(ABS(D5:D12-B5:B12))/8 -> 0.20125 | D17: =SUMPRODUCT(ABS(E5:E12-B5:B12))/8 -> 6.62125
A18: Average posterior SD (raw: average SE) | B18: =AVERAGE(C5:C12) -> 12.65 | C18: =AVERAGE(G5:G12) -> 12.71625 | D18: =AVERAGE(H5:H12) -> 6.2575
A19: Average 95% interval width | C19: =AVERAGE(L5:L12) -> 49.51875 | D19: =AVERAGE(O5:O12) -> 25.04375
A20: Schools whose 95% interval excludes 0 | C20: =COUNTIF(Q5:Q12,"No") -> 1 | D20: =COUNTIF(R5:R12,"No") -> 0
A21: Average width reduction from pooling | D21: =AVERAGE(P5:P12) -> 0.47961312
A24: Takeaways
A25: - No pooling just reproduces the data: non-hierarchical means sit within about 0.2 points (on average) of the raw estimates and posterior SDs (avg 12.7) match the raw SEs (avg 12.7). The model adds no information.
A26: - Hierarchical partial pooling collapses the spread of school means from about 31.8 to 4.4 points and halves interval widths (average width 49.5 -> 25.0, about 49% narrower).
A27: - Substantive difference: in the non-hierarchical model School A's 95% interval (0.62 to 58.11) excludes 0, so it looks like a clear success. In the hierarchical model it includes 0 (-1.31 to 27.20) and the mean falls from 28.8 to 10.4.
A28: - Schools with the largest SEs (C, H) gain most from pooling: interval widths shrink by 58% and 61%, and School C's mean moves from -3.0 to +6.7.
A29: - Both models converged (Rhat <= 1.01, n_eff > 2,600 for all mu in the non-hierarchical run; Rhat 1.00 throughout in the hierarchical run).
A30: - Caveat: the non-hierarchical posterior is driven entirely by each school's single estimate with a flat prior; the hierarchical result depends on the beta prior (see 'Prior Sensitivity'), though its conclusions are stable across the priors tried.

Sheet School Shrinkage
A1: Partial Pooling: Raw Estimates vs Posterior School Effects
A2: Blue = raw data supplied by user (eight schools data); green = links to 'Posterior Summary'; black = formulas.
A4: School | B4: Raw estimate | C4: Raw SE | D4: Raw z (est/SE) | E4: Posterior mean (mu) | F4: Change (post - raw) | G4: Post. 2.5% | H4: Post. 97.5% | I4: 95% interval width | J4: Interval includes 0? | K4: Posterior SD
A5: A | B5: 28.39 | C5: 14.9 | D5: =B5/C5 -> 1.9053691 | E5: ='Posterior Summary'!C16 -> 10.4 | F5: =E5-B5 -> -17.99 | G5: ='Posterior Summary'!F16 -> -1.31 | H5: ='Posterior Summary'!J16 -> 27.2 | I5: =H5-G5 -> 28.51 | J5: =IF(AND(G5<=0,H5>=0),"Yes","No") -> Yes | K5: ='Posterior Summary'!E16 -> 7.17
A6: B | B6: 7.94 | C6: 10.2 | D6: =B6/C6 -> 0.77843137 | E6: ='Posterior Summary'!C17 -> 7.85 | F6: =E6-B6 -> -0.09 | G6: ='Posterior Summary'!F17 -> -3.22 | H6: ='Posterior Summary'!J17 -> 19.37 | I6: =H6-G6 -> 22.59 | J6: =IF(AND(G6<=0,H6>=0),"Yes","No") -> Yes | K6: ='Posterior Summary'!E17 -> 5.58
A7: C | B7: -2.75 | C7: 16.3 | D7: =B7/C7 -> -0.16871166 | E7: ='Posterior Summary'!C18 -> 6.74 | F7: =E7-B7 -> 9.49 | G7: ='Posterior Summary'!F18 -> -8.15 | H7: ='Posterior Summary'!J18 -> 18.92 | I7: =H7-G7 -> 27.07 | J7: =IF(AND(G7<=0,H7>=0),"Yes","No") -> Yes | K7: ='Posterior Summary'!E18 -> 6.76
A8: D | B8: 6.82 | C8: 11 | D8: =B8/C8 -> 0.62 | E8: ='Posterior Summary'!C19 -> 7.47 | F8: =E8-B8 -> 0.65 | G8: ='Posterior Summary'!F19 -> -3.78 | H8: ='Posterior Summary'!J19 -> 19.38 | I8: =H8-G8 -> 23.16 | J8: =IF(AND(G8<=0,H8>=0),"Yes","No") -> Yes | K8: ='Posterior Summary'!E19 -> 5.79
A9: E | B9: -0.64 | C9: 9.4 | D9: =B9/C9 -> -0.068085106 | E9: ='Posterior Summary'!C20 -> 6 | F9: =E9-B9 -> 6.64 | G9: ='Posterior Summary'!F20 -> -6.37 | H9: ='Posterior Summary'!J20 -> 16.51 | I9: =H9-G9 -> 22.88 | J9: =IF(AND(G9<=0,H9>=0),"Yes","No") -> Yes | K9: ='Posterior Summary'!E20 -> 5.83
A10: F | B10: 0.63 | C10: 11.4 | D10: =B10/C10 -> 0.055263158 | E10: ='Posterior Summary'!C21 -> 6.57 | F10: =E10-B10 -> 5.94 | G10: ='Posterior Summary'!F21 -> -6.95 | H10: ='Posterior Summary'!J21 -> 17.86 | I10: =H10-G10 -> 24.81 | J10: =IF(AND(G10<=0,H10>=0),"Yes","No") -> Yes | K10: ='Posterior Summary'!E21 -> 6.23
A11: G | B11: 18.01 | C11: 10.4 | D11: =B11/C11 -> 1.7317308 | E11: ='Posterior Summary'!C22 -> 9.85 | F11: =E11-B11 -> -8.16 | G11: ='Posterior Summary'!F22 -> -1.44 | H11: ='Posterior Summary'!J22 -> 23.72 | I11: =H11-G11 -> 25.16 | J11: =IF(AND(G11<=0,H11>=0),"Yes","No") -> Yes | K11: ='Posterior Summary'!E22 -> 6.16
A12: H | B12: 12.16 | C12: 17.6 | D12: =B12/C12 -> 0.69090909 | E12: ='Posterior Summary'!C23 -> 8.15 | F12: =E12-B12 -> -4.01 | G12: ='Posterior Summary'!F23 -> -4.32 | H12: ='Posterior Summary'!J23 -> 21.85 | I12: =H12-G12 -> 26.17 | J12: =IF(AND(G12<=0,H12>=0),"Yes","No") -> Yes | K12: ='Posterior Summary'!E23 -> 6.54
A14: Summary of shrinkage
A15: Population mean (alpha) | B15: ='Posterior Summary'!C6 -> 7.73
A16: Range of raw estimates | B16: =MAX(B5:B12)-MIN(B5:B12) -> 31.14
A17: Range of posterior means | B17: =MAX(E5:E12)-MIN(E5:E12) -> 4.4
A18: Spread retained after pooling | B18: =B17/B16 -> 0.14129737
A19: Largest absolute shrinkage (points) | B19: =MAX(MAX(F5:F12),-MIN(F5:F12)) -> 17.99
A20: Schools whose 95% interval excludes 0 | B20: =COUNTIF(J5:J12,"No") -> 0
A22: Interpretation: extreme raw estimates with large SEs (A, C) are pulled strongly toward the overall mean; posterior intervals are wide, so schools cannot be confidently ranked.

Sheet Prior Sensitivity
A1: Prior Sensitivity: how the prior on beta changes beta and mu
A2: Method: exact posterior (alpha and school effects integrated analytically, grid over beta), 400,000 draws, seed 1; alpha ~ normal(0,20) in all runs. Baseline matches the Stan run. Blue = computed outside this workbook; green = link to another sheet; black = formula.
A4: 1. beta (between-school SD)
A5: Prior on beta | B5: Mean | C5: Median | D5: 2.5% | E5: 97.5% | F5: 95% interval width | G5: P(beta < 1) | H5: P(beta < 2)
A6: HN(0,10) original | B6: 4.7951576 | C6: 3.9926778 | D6: 0.18551294 | E6: 13.887774 | F6: =E6-D6 -> 13.702261 | G6: 0.13414 | H6: 0.264985
A7: HN(0,5) | B7: 3.2885747 | C7: 2.7803328 | D7: 0.12752546 | E7: 9.2669231 | F7: =E7-D7 -> 9.1393976 | G7: 0.1921525 | H7: 0.37227
A8: HC(0,5) | B8: 3.5953029 | C8: 2.7334066 | D8: 0.12230983 | E8: 11.995791 | F8: =E8-D8 -> 11.873481 | G8: 0.20064 | H8: 0.3833975
A9: HC(0,2.5) | B9: 2.5441294 | C9: 1.7655097 | D9: 0.074173821 | E9: 9.5658789 | F9: =E9-D9 -> 9.4917051 | G9: 0.31164 | H9: 0.5476875
A12: 2. mu: posterior means by school
A13: School | B13: Raw estimate | C13: HN(0,10) original | D13: HN(0,5) | E13: HC(0,5) | F13: HC(0,2.5) | G13: Change: HN(0,5) vs original | H13: Change: HC(0,5) vs original
A14: A | B14: ='School Shrinkage'!B5 -> 28.39 | C14: 10.011829 | D14: 8.894657 | E14: 9.1805287 | F14: 8.5245028 | G14: =D14-C14 -> -1.1171716 | H14: =E14-C14 -> -0.83129998
A15: B | B15: ='School Shrinkage'!B6 -> 7.94 | C15: 7.6749473 | D15: 7.6060639 | E15: 7.6363091 | F15: 7.5980874 | G15: =D15-C15 -> -0.068883466 | H15: =E15-C15 -> -0.038638194
A16: C | B16: ='School Shrinkage'!B7 -> -2.75 | C16: 6.5490146 | D16: 7.0243453 | E16: 6.898718 | F16: 7.1775269 | G16: =D16-C16 -> 0.47533071 | H16: =E16-C16 -> 0.34970347
A17: D | B17: ='School Shrinkage'!B8 -> 6.82 | C17: 7.4681696 | D17: 7.496388 | E17: 7.4874338 | F17: 7.5183318 | G17: =D17-C17 -> 0.028218435 | H17: =E17-C17 -> 0.019264203
A18: E | B18: ='School Shrinkage'!B9 -> -0.64 | C18: 5.8333909 | D18: 6.5007935 | E18: 6.3748201 | F18: 6.8098675 | G18: =D18-C18 -> 0.6674026 | H18: =E18-C18 -> 0.54142923
A19: F | B19: ='School Shrinkage'!B10 -> 0.63 | C19: 6.4285518 | D19: 6.8942865 | E19: 6.8012599 | F19: 7.0911099 | G19: =D19-C19 -> 0.46573463 | H19: =E19-C19 -> 0.3727081
A20: G | B20: ='School Shrinkage'!B11 -> 18.01 | C20: 9.5766331 | D20: 8.7552718 | E20: 8.9283174 | F20: 8.4047641 | G20: =D20-C20 -> -0.82136129 | H20: =E20-C20 -> -0.64831569
A21: H | B21: ='School Shrinkage'!B12 -> 12.16 | C21: 8.0171082 | D21: 7.8082627 | E21: 7.8653237 | F21: 7.7354606 | G21: =D21-C21 -> -0.20884552 | H21: =E21-C21 -> -0.1517845
A22: Range of values | B22: =MAX(B14:B21)-MIN(B14:B21) -> 31.14 | C22: =MAX(C14:C21)-MIN(C14:C21) -> 4.1784378 | D22: =MAX(D14:D21)-MIN(D14:D21) -> 2.3938636 | E22: =MAX(E14:E21)-MIN(E14:E21) -> 2.8057086 | F22: =MAX(F14:F21)-MIN(F14:F21) -> 1.7146353
A23: Spread retained vs raw | C23: =C22/$B$22 -> 0.13418233 | D23: =D22/$B$22 -> 0.076874231 | E23: =E22/$B$22 -> 0.090099826 | F23: =F22/$B$22 -> 0.055062148
A25: 3. mu: 95% interval lower bound (2.5%)
A26: School | B26: HN(0,10) original | C26: HN(0,5) | D26: HC(0,5) | E26: HC(0,2.5)
A27: A | B27: -1.9163044 | C27: -1.5286486 | D27: -1.5390316 | E27: -1.155143
A28: B | B28: -3.782792 | C28: -2.553678 | D28: -2.8033956 | E28: -1.9392512
A29: C | B29: -7.9776824 | C29: -4.6305473 | D29: -5.6534057 | E29: -3.4888998
A30: D | B30: -4.4169805 | C30: -2.9173538 | D30: -3.2944366 | E30: -2.2081321
A31: E | B31: -6.8098522 | C31: -4.3199263 | D31: -5.0170411 | E31: -3.3832887
A32: F | B32: -6.6090602 | C32: -4.0906546 | D32: -4.8015959 | E32: -3.1588362
A33: G | B33: -1.3607324 | C33: -1.1261146 | D33: -1.138929 | E33: -0.92743494
A34: H | B34: -5.084648 | C34: -3.1589606 | D34: -3.6246676 | E34: -2.3408927
A36: 4. mu: 95% interval upper bound (97.5%)
A37: School | B37: HN(0,10) original | C37: HN(0,5) | D37: HC(0,5) | E37: HC(0,2.5)
A38: A | B38: 26.306228 | C38: 21.374218 | D38: 23.296706 | E38: 20.239012
A39: B | B39: 19.281566 | C39: 17.830618 | D39: 18.190818 | E39: 17.205787
A40: C | B40: 19.130292 | C40: 17.786794 | D40: 18.011999 | E40: 17.121907
A41: D | B41: 19.209075 | C41: 17.862783 | D41: 18.147151 | E41: 17.251996
A42: E | B42: 16.47083 | C42: 16.25033 | D42: 16.236371 | E42: 16.033099
A43: F | B43: 17.838346 | C43: 17.044533 | D43: 17.144768 | E43: 16.617053
A44: G | B44: 23.098924 | C44: 20.061443 | D44: 21.051852 | E44: 19.044754
A45: H | B45: 22.119614 | C45: 19.301533 | D45: 19.983288 | E45: 18.216879
...

Sheet Interpretation
A1: Interpretation of Results
A3: Topic | B3: Finding | C3: What it means
A4: Convergence | B4: All Rhat = 1.00; n_eff from 733 (lp__) to 2700; 4 chains, 2000 draws. | C4: The sampler converged and mixed well. The earlier Rhat problem is resolved (shared hyperparameters + non-centered parameterization).
A5: alpha (population mean effect) | B5: Mean 7.7, median 7.7, 95% interval -1.2 to 16.7. | C5: Average effect is probably positive (~8 points), but the interval includes 0, so a positive effect is plausible, not conclusive.
A6: beta (between-school SD) | B6: Median 4.0 (mean 4.9), 95% interval 0.2 to 14.3; right-skewed. | C6: Very uncertain: from 'all schools essentially identical' to 'substantial differences'. Data cannot pin this down with 8 schools.
A7: eta (standardized offsets) | B7: Means between -0.27 and +0.36, SDs near 1 (about the std_normal prior). | C7: Data barely move eta from the prior: weak evidence of school-to-school differences. Not normally interpreted directly.
A8: mu (school effects) | B8: Posterior means range 6.0 to 10.4; 95% intervals are wide (e.g. School A: -1.3 to 27.2). | C8: Strong partial pooling. Raw extremes shrink toward the mean (A: 28.4 -> 10.4; C: -2.75 -> 6.7).
A9: Ranking schools | B9: Posterior intervals overlap heavily. | C9: Do not read the order of mu means as a ranking of school quality.
A10: Bottom line | B10: Overall effect likely positive (~8 pts) with considerable uncertainty; little evidence any school truly differs. | C10: School A's high raw estimate is largely within what noise would produce.
A11: Caveat: prior sensitivity | B11: beta ~ half-normal(0, 10) influences the wide upper tail with only 8 schools. | C11: Re-run with normal(0, 5) or half-Cauchy and compare beta and mu before drawing firm conclusions.
A12: Non-hierarchical (no pooling) model | B12: Posterior means equal the raw estimates (28.8, 7.9, -3.0, 7.1, -0.7, 0.6, 17.8, 11.9); posterior SDs match the raw SEs; 95% intervals are very wide (average width 49.5). Converged: Rhat <= 1.01, n_eff > 2,600. | C12: Treats each school in isolation. School A's interval (0.6 to 58.1) excludes 0, suggesting a clear effect, while all other schools' intervals include 0.
A13: Hierarchical vs non-hierarchical | B13: Hierarchical shrinks the spread of school means from 31.8 to 4.4 points and cuts average interval width by about half (49.5 -> 25.0). School A: 28.8 -> 10.4, interval now includes 0. | C13: Partial pooling prevents over-reading noisy extreme estimates. The no-pooling result for School A is likely inflated by sampling noise; the hierarchical result is the more credible summary.

Sheet Model & Notes
A1: Model Specification and Assumptions
A3: Model (non-centered hierarchical):
A4: alpha ~ normal(0, 20) population mean effect
A5: beta ~ normal(0, 10) half-normal (lower=0), between-school SD
A6: eta[j] ~ std_normal() standardized school offsets
A7: mu[j] = alpha + beta * eta[j] school-level effect
A8: treatment[j] ~ normal(mu[j], standard_error[j])
A10: Sources and assumptions:
A12: {=- Raw estimates and standard errors are the classic eight schools data A2} -> #NAME?
A13: - Priors on alpha and beta are weakly informative choices on the scale of the data (my suggestion, not a requirement).
A14: - Interval columns use the 95% credible interval (2.5% to 97.5%).
A15: - Formula columns (n_eff / draws, includes-0 flags, shrinkage stats) recalculate if inputs change.
A18: Non-hierarchical model (for comparison):
A19: treatment[j] ~ normal(mu[j], standard_error[j]) independent mu[j] per school, flat prior
A20: - 'Model Comparison' sets this model against the hierarchical run using beta ~ half-normal(0, 10).
